<?xml version="1.0" ?>
<!-- =================================================================================== -->
<!-- |    This document was autogenerated by xacro from ../urdf/husky.urdf.xacro       | -->
<!-- |    EDITING THIS FILE BY HAND IS NOT RECOMMENDED                                 | -->
<!-- =================================================================================== -->
<!--
Software License Agreement (BSD)

\file      husky.urdf.xacro
\authors   Paul Bovbel <pbovbel@clearpathrobotics.com>
\copyright Copyright (c) 2015, Clearpath Robotics, Inc., All rights reserved.

Redistribution and use in source and binary forms, with or without modification, are permitted provided that
the following conditions are met:
 * Redistributions of source code must retain the above copyright notice, this list of conditions and the
   following disclaimer.
 * Redistributions in binary form must reproduce the above copyright notice, this list of conditions and the 
   following disclaimer in the documentation and/or other materials provided with the distribution.
 * Neither the name of Clearpath Robotics nor the names of its contributors may be used to endorse or promote
   products derived from this software without specific prior written permission.

THIS SOFTWARE IS PROVIDED BY THE COPYRIGHT HOLDERS AND CONTRIBUTORS "AS IS" AND ANY EXPRESS OR IMPLIED WAR-
RANTIES, INCLUDING, BUT NOT LIMITED TO, THE IMPLIED WARRANTIES OF MERCHANTABILITY AND FITNESS FOR A PARTICULAR
PURPOSE ARE DISCLAIMED. IN NO EVENT SHALL THE COPYRIGHT HOLDER OR CONTRIBUTORS BE LIABLE FOR ANY DIRECT, IN-
DIRECT, INCIDENTAL, SPECIAL, EXEMPLARY, OR CONSEQUENTIAL DAMAGES (INCLUDING, BUT NOT LIMITED TO, PROCUREMENT
OF SUBSTITUTE GOODS OR SERVICES; LOSS OF USE, DATA, OR PROFITS; OR BUSINESS INTERRUPTION) HOWEVER CAUSED AND
ON ANY THEORY OF LIABILITY, WHETHER IN CONTRACT, STRICT LIABILITY, OR TORT (INCLUDING NEGLIGENCE OR OTHERWISE)
ARISING IN ANY WAY OUT OF THE USE OF THIS SOFTWARE, EVEN IF ADVISED OF THE POSSIBILITY OF SUCH DAMAGE.
-->
<robot name="husky_robot">
  <!-- Chassis link is the center of the robot's bottom plate -->
  <link name="base_link">
    <visual>
      <origin rpy="0 0 0" xyz="0 0 0"/>
      <geometry>
        <mesh filename="meshes/base_link.dae"/>
      </geometry>
      <material name="Black">
        <color rgba="0.1 0.1 0.1 1.0"/>
      </material>
    </visual>
    <collision>
      <origin rpy="0 0 0" xyz="0 0 0.12498"/>
      <geometry>
        <!-- Make collision box slightly bigger in x and z directions. -->
        <box size="0.8675 0.44 0.25"/>
      </geometry>
    </collision>
    <inertial>
      <mass value="33.455"/>
      <origin xyz="-0.08748 -0.00085 0.09947"/>
      <inertia ixx="0.6022" ixy="-0.02364" ixz="-0.1197" iyy="1.7386" iyz="-0.001544" izz="2.0296"/>
    </inertial>
  </link>

  <!-- Husky wheel macros -->
  <link name="front_left_wheel_link">
    <inertial>
      <mass value="2.637"/>
      <origin xyz="0 0 0"/>
      <inertia ixx="0.02467" ixy="0" ixz="0" iyy="0.02467" iyz="0" izz="0.04411"/>
    </inertial>
    <visual>
      <origin rpy="0 0 0" xyz="0 0 0"/>
      <geometry>
        <mesh filename="meshes/wheel.dae"/>
      </geometry>
      <material name="DarkGrey">
        <color rgba="0.3 0.3 0.3 1.0"/>
      </material>
    </visual>
    <collision>
      <origin rpy="0 0 0" xyz="0.05775 0 0.09216"/>
      <geometry>
        <box size="0.24 0.1143 0.25"/>
      </geometry>
    </collision>
  </link>

  <joint name="front_left_wheel" type="fixed">
    <parent link="base_link"/>
    <child link="front_left_wheel_link"/>
    <origin rpy="0 0 0" xyz="0.256 0.2854 0.03282"/>
    <axis rpy="0 0 0" xyz="0 1 0"/>
  </joint>

  <link name="front_right_wheel_link">
    <inertial>
      <mass value="2.637"/>
      <origin xyz="0 0 0"/>
      <inertia ixx="0.02467" ixy="0" ixz="0" iyy="0.02467" iyz="0" izz="0.04411"/>
    </inertial>
    <visual>
      <origin rpy="0 0 0" xyz="0 0 0"/>
      <geometry>
        <mesh filename="meshes/wheel.dae"/>
      </geometry>
      <material name="DarkGrey">
        <color rgba="0.3 0.3 0.3 1.0"/>
      </material>
    </visual>
    <collision>
      <origin rpy="0 0 0" xyz="0.05775 0 0.09216"/>
      <geometry>
        <box size="0.24 0.1143 0.25"/>
      </geometry>
    </collision>
  </link>

  <joint name="front_right_wheel" type="fixed">
    <parent link="base_link"/>
    <child link="front_right_wheel_link"/>
    <origin rpy="0 0 0" xyz="0.256 -0.2854 0.03282"/>
    <axis rpy="0 0 0" xyz="0 1 0"/>
  </joint>

  <link name="rear_left_wheel_link">
    <inertial>
      <mass value="2.637"/>
      <origin xyz="0 0 0"/>
      <inertia ixx="0.02467" ixy="0" ixz="0" iyy="0.02467" iyz="0" izz="0.04411"/>
    </inertial>
    <visual>
      <origin rpy="0 0 0" xyz="0 0 0"/>
      <geometry>
        <mesh filename="meshes/wheel.dae"/>
      </geometry>
      <material name="DarkGrey">
        <color rgba="0.3 0.3 0.3 1.0"/>
      </material>
    </visual>
    <collision>
      <origin rpy="0 0 0" xyz="-0.05775 0 0.09216"/>
      <geometry>
        <box size="0.24 0.1143 0.25"/>
      </geometry>
    </collision>
  </link>

  <joint name="rear_left_wheel" type="fixed">
    <parent link="base_link"/>
    <child link="rear_left_wheel_link"/>
    <origin rpy="0 0 0" xyz="-0.256 0.2854 0.03282"/>
    <axis rpy="0 0 0" xyz="0 1 0"/>
  </joint>

  <link name="rear_right_wheel_link">
    <inertial>
      <mass value="2.637"/>
      <origin xyz="0 0 0"/>
      <inertia ixx="0.02467" ixy="0" ixz="0" iyy="0.02467" iyz="0" izz="0.04411"/>
    </inertial>
    <visual>
      <origin rpy="0 0 0" xyz="0 0 0"/>
      <geometry>
        <mesh filename="meshes/wheel.dae"/>
      </geometry>
      <material name="DarkGrey">
        <color rgba="0.3 0.3 0.3 1.0"/>
      </material>
    </visual>
    <collision>
      <origin rpy="0 0 0" xyz="-0.05775 0 0.09216"/>
      <geometry>
        <box size="0.24 0.1143 0.25"/>
      </geometry>
    </collision>
  </link>

  <joint name="rear_right_wheel" type="fixed">
    <parent link="base_link"/>
    <child link="rear_right_wheel_link"/>
    <origin rpy="0 0 0" xyz="-0.256 -0.2854 0.03282"/>
    <axis rpy="0 0 0" xyz="0 1 0"/>
  </joint>

  <link name="top_plate_link">
    <visual>
      <origin rpy="0 0 0" xyz="0 0 0"/>
      <geometry>
        <mesh filename="meshes/top_plate.dae"/>
      </geometry>
      <material name="Yellow">
        <color rgba="0.8 0.8 0.0 1.0"/>
      </material>
    </visual>
  </link>

  <joint name="top_plate" type="fixed">
    <parent link="base_link"/>
    <child link="top_plate_link"/>
  </joint>

  <link name="user_rail_link">
    <visual>
      <geometry>
        <mesh filename="meshes/user_rail.dae"/>
      </geometry>
      <material name="DarkGrey">
        <color rgba="0.3 0.3 0.3 1.0"/>
      </material>
    </visual>
  </link>

  <joint name="user_rail" type="fixed">
    <origin rpy="0 0 0" xyz="0.272 0 0.245"/>
    <parent link="base_link"/>
    <child link="user_rail_link"/>
  </joint>

  <link name="front_bumper_link">
    <visual>
      <geometry>
        <mesh filename="meshes/bumper.dae"/>
      </geometry>
      <material name="DarkGrey">
        <color rgba="0.3 0.3 0.3 1.0"/>
      </material>
    </visual>
  </link>

  <joint name="front_bumper" type="fixed">
    <origin rpy="0 0 0" xyz="0.48 0 0.091"/>
    <parent link="base_link"/>
    <child link="front_bumper_link"/>
  </joint>

  <link name="rear_bumper_link">
    <visual>
      <geometry>
        <mesh filename="meshes/bumper.dae"/>
      </geometry>
      <material name="DarkGrey">
        <color rgba="0.3 0.3 0.3 1.0"/>
      </material>
    </visual>
  </link>

  <joint name="rear_bumper" type="fixed">
    <origin rpy="0 0 3.14159" xyz="-0.48 0 0.091"/>
    <parent link="base_link"/>
    <child link="rear_bumper_link"/>
  </joint>

  <!-- fake wheel -->

	<link name="left_wheel_link">
		<collision>
      <origin rpy="1.570795 0 0" xyz="0 0 0"/>
			<geometry>
        <cylinder length="0.1143" radius="0.17775"/>
			</geometry>
		</collision>

		<inertial>
			<origin rpy="0 0 0" xyz="0 0 0"/>
			<mass value="2.637"/>
		</inertial>
	</link>

	<joint name="left_wheel" type="continuous">
    <parent link="base_link"/>
		<child link="left_wheel_link"/>
		<origin rpy="0 0 0" xyz="0.0 0.2854 0.03282"/>
		<axis xyz="0 1 0"/>
	</joint>

	<link name="right_wheel_link">
		<collision>
      <origin rpy="1.570795 0 0" xyz="0 0 0"/>
			<geometry>
        <cylinder length="0.1143" radius="0.17775"/>
			</geometry>
		</collision>

		<inertial>
			<origin rpy="0 0 0" xyz="0 0 0"/>
			<mass value="2.637"/>
		</inertial>
	</link>

	<joint name="right_wheel" type="continuous">
    <parent link="base_link"/>
		<child link="right_wheel_link"/>
    <origin rpy="0 0 0" xyz="0.0 -0.2854 0.03282"/>
		<axis xyz="0 1 0"/>
	</joint>

	<link name="front_ball">
		<collision>
			<geometry>
				<sphere radius="0.071"/>
			</geometry>
		</collision>
	</link>

	<joint name="front_ball_joint" type="fixed">
    <parent link="base_link"/>
		<child link="front_ball"/>
		<origin rpy="0 0 0" xyz="0.35 0 -0.073"/>
		<axis xyz="0 1 0"/>
	</joint>

	<link name="rear_ball">
		<collision>
			<geometry>
				<sphere radius="0.071"/>
			</geometry>
		</collision>
	</link>

	<joint name="rear_ball_joint" type="fixed">
    <parent link="base_link"/>
		<child link="rear_ball"/>
		<origin rpy="0 0 0" xyz="-0.35 0 -0.073"/>
		<axis xyz="0 1 0"/>
	</joint>

	<!-- franka panda -->

	<link name="panda_link0">
		<visual>
			<geometry>
				<mesh filename="meshes/visual/link0.dae"/>
			</geometry>
		</visual>
		<collision>
			<geometry>
				<mesh filename="meshes/collision/link0.obj"/>
			</geometry>
		</collision>
	</link>

	<joint name="base_panda" type="fixed">
		<parent link="base_link"/>
		<child link="panda_link0"/>
		<origin rpy="0 0 0" xyz="0.1 0 0.2"/>
		<axis xyz="0 0 1"/>
	</joint>

	<link name="panda_link1">
		<visual>
			<geometry>
				<mesh filename="meshes/visual/link1.dae"/>
			</geometry>
		</visual>
		<collision>
			<geometry>
				<mesh filename="meshes/collision/link1.obj"/>
			</geometry>
		</collision>
	</link>

	<joint name="panda_joint1" type="revolute">
		<safety_controller k_position="100.0" k_velocity="40.0" soft_lower_limit="-2.8973" soft_upper_limit="2.8973"/>
		<origin rpy="0 0 0" xyz="0 0 0.333"/>
		<parent link="panda_link0"/>
		<child link="panda_link1"/>
		<axis xyz="0 0 1"/>
		<dynamics damping="10.0"/>
		<limit effort="87" lower="-2.8973" upper="2.8973" velocity="2.1750"/>
	</joint>

	<link name="panda_link2">
		<visual>
			<geometry>
				<mesh filename="meshes/visual/link2.dae"/>
			</geometry>
		</visual>
		<collision>
			<geometry>
				<mesh filename="meshes/collision/link2.obj"/>
			</geometry>
		</collision>
	</link>

	<joint name="panda_joint2" type="revolute">
		<safety_controller k_position="100.0" k_velocity="40.0" soft_lower_limit="-1.7628" soft_upper_limit="1.7628"/>
		<origin rpy="-1.57079632679 0 0" xyz="0 0 0"/>
		<parent link="panda_link1"/>
		<child link="panda_link2"/>
		<axis xyz="0 0 1"/>
		<dynamics damping="10.0"/>
		<limit effort="87" lower="-1.7628" upper="1.7628" velocity="2.1750"/>
	</joint>

	<link name="panda_link3">
		<visual>
			<geometry>
				<mesh filename="meshes/visual/link3.dae"/>
			</geometry>
		</visual>
		<collision>
			<geometry>
				<mesh filename="meshes/collision/link3.obj"/>
			</geometry>
		</collision>
	</link>

	<joint name="panda_joint3" type="revolute">
		<safety_controller k_position="100.0" k_velocity="40.0" soft_lower_limit="-2.8973" soft_upper_limit="2.8973"/>
		<origin rpy="1.57079632679 0 0" xyz="0 -0.316 0"/>
		<parent link="panda_link2"/>
		<child link="panda_link3"/>
		<axis xyz="0 0 1"/>
		<dynamics damping="10.0"/>
		<limit effort="87" lower="-2.8973" upper="2.8973" velocity="2.1750"/>
	</joint>

	<link name="panda_link4">
		<visual>
			<geometry>
				<mesh filename="meshes/visual/link4.dae"/>
			</geometry>
		</visual>
		<collision>
			<geometry>
				<mesh filename="meshes/collision/link4.obj"/>
			</geometry>
		</collision>
	</link>

	<joint name="panda_joint4" type="revolute">
		<safety_controller k_position="100.0" k_velocity="40.0" soft_lower_limit="-3.0718" soft_upper_limit="-0.0698"/>
		<origin rpy="1.57079632679 0 0" xyz="0.0825 0 0"/>
		<parent link="panda_link3"/>
		<child link="panda_link4"/>
		<axis xyz="0 0 1"/>    
		<dynamics damping="10.0"/>
		<limit effort="87" lower="-3.0718" upper="-0.0698" velocity="2.1750"/>
		<!-- something is weird with this joint limit config
		<dynamics damping="10.0"/>
		<limit effort="87" lower="-3.0" upper="0.087" velocity="2.1750"/>  -->
	</joint>

	<link name="panda_link5">
		<visual>
			<geometry>
				<mesh filename="meshes/visual/link5.dae"/>
			</geometry>
		</visual>
		<collision>
			<geometry>
				<mesh filename="meshes/collision/link5.obj"/>
			</geometry>
		</collision>
	</link>

	<joint name="panda_joint5" type="revolute">
		<safety_controller k_position="100.0" k_velocity="40.0" soft_lower_limit="-2.8973" soft_upper_limit="2.8973"/>
		<origin rpy="-1.57079632679 0 0" xyz="-0.0825 0.384 0"/>
		<parent link="panda_link4"/>
		<child link="panda_link5"/>
		<axis xyz="0 0 1"/>
		<dynamics damping="10.0"/>
		<limit effort="12" lower="-2.8973" upper="2.8973" velocity="2.6100"/>
	</joint>

	<link name="panda_link6">
		<visual>
			<geometry>
				<mesh filename="meshes/visual/link6.dae"/>
			</geometry>
		</visual>
		<collision>
			<geometry>
				<mesh filename="meshes/collision/link6.obj"/>
			</geometry>
		</collision>
	</link>

	<joint name="panda_joint6" type="revolute">
		<safety_controller k_position="100.0" k_velocity="40.0" soft_lower_limit="-0.0175" soft_upper_limit="3.7525"/>
		<origin rpy="1.57079632679 0 0" xyz="0 0 0"/>
		<parent link="panda_link5"/>
		<child link="panda_link6"/>
		<axis xyz="0 0 1"/>
		<dynamics damping="10.0"/>
		<limit effort="12" lower="-0.0175" upper="3.7525" velocity="2.6100"/>
		<!-- <dynamics damping="10.0"/>
		<limit effort="12" lower="-0.0873" upper="3.0" velocity="2.6100"/> -->
	</joint>

	<link name="panda_link7">
		<visual>
			<geometry>
				<mesh filename="meshes/visual/link7.dae"/>
			</geometry>
		</visual>
		<collision>
			<geometry>
				<mesh filename="meshes/collision/link7.obj"/>
			</geometry>
		</collision>
	</link>

	<joint name="panda_joint7" type="revolute">
		<safety_controller k_position="100.0" k_velocity="40.0" soft_lower_limit="-2.8973" soft_upper_limit="2.8973"/>
		<origin rpy="1.57079632679 0 0" xyz="0.088 0 0"/>
		<parent link="panda_link6"/>
		<child link="panda_link7"/>
		<axis xyz="0 0 1"/>
		<dynamics damping="10.0"/>
		<limit effort="12" lower="-2.8973" upper="2.8973" velocity="2.6100"/>
	</joint>

	<link name="panda_hand">
		<visual>
			<geometry>
				<mesh filename="meshes/visual/hand.dae"/>
			</geometry>
		</visual>
		<collision>
			<geometry>
				<mesh filename="meshes/collision/hand.obj"/>
			</geometry>
		</collision>
	</link>

	<joint name="panda_hand_joint" type="fixed">
		<parent link="panda_link7"/>
		<child link="panda_hand"/>
		<origin rpy="0 0 -0.785398163397" xyz="0 0 0.107"/>
	</joint>

	<link name="panda_leftfinger">
		<visual>
			<geometry>
				<mesh filename="meshes/visual/finger.dae"/>
			</geometry>
		</visual>
		<collision>
			<geometry>
				<mesh filename="meshes/collision/finger.obj"/>
			</geometry>
		</collision>
	</link>

	<joint name="panda_finger_joint1" type="prismatic">
		<parent link="panda_hand"/>
		<child link="panda_leftfinger"/>
		<origin rpy="0 0 0" xyz="0 0 0.0584"/>
		<axis xyz="0 1 0"/>
		<dynamics damping="10.0"/>
		<limit effort="20" lower="0.0" upper="0.04" velocity="0.2"/>
	</joint>

	<link name="panda_rightfinger">
		<visual>
			<origin rpy="0 0 3.14159265359" xyz="0 0 0"/>
			<geometry>
				<mesh filename="meshes/visual/finger.dae"/>
			</geometry>
		</visual>
		<collision>
			<origin rpy="0 0 3.14159265359" xyz="0 0 0"/>
			<geometry>
				<mesh filename="meshes/collision/finger.obj"/>
			</geometry>
		</collision>
	</link>

	<joint name="panda_finger_joint2" type="prismatic">
		<parent link="panda_hand"/>
		<child link="panda_rightfinger"/>
		<origin rpy="0 0 0" xyz="0 0 0.0584"/>
		<axis xyz="0 -1 0"/>
		<dynamics damping="10.0"/>
		<limit effort="20" lower="0.0" upper="0.04" velocity="0.2"/>
		<mimic joint="panda_finger_joint1"/>
	</joint>

</robot>

